[2025-07-25T01:15:40.178+0000] {taskinstance.py:1956} INFO - Dependencies all met for dep_context=non-requeueable deps ti=<TaskInstance: bis_pipeline_dag.kafka_to_bronze manual__2025-07-25T01:15:35.843105+00:00 [queued]>
[2025-07-25T01:15:40.183+0000] {taskinstance.py:1956} INFO - Dependencies all met for dep_context=requeueable deps ti=<TaskInstance: bis_pipeline_dag.kafka_to_bronze manual__2025-07-25T01:15:35.843105+00:00 [queued]>
[2025-07-25T01:15:40.183+0000] {taskinstance.py:2170} INFO - Starting attempt 1 of 1
[2025-07-25T01:15:40.257+0000] {taskinstance.py:2191} INFO - Executing <Task(DockerOperator): kafka_to_bronze> on 2025-07-25 01:15:35.843105+00:00
[2025-07-25T01:15:40.260+0000] {standard_task_runner.py:60} INFO - Started process 190 to run task
[2025-07-25T01:15:40.262+0000] {standard_task_runner.py:87} INFO - Running: ['airflow', 'tasks', 'run', 'bis_pipeline_dag', 'kafka_to_bronze', 'manual__2025-07-25T01:15:35.843105+00:00', '--job-id', '12', '--raw', '--subdir', 'DAGS_FOLDER/bis_pipeline_dag.py', '--cfg-path', '/tmp/tmp4gtvu763']
[2025-07-25T01:15:40.263+0000] {standard_task_runner.py:88} INFO - Job 12: Subtask kafka_to_bronze
[2025-07-25T01:15:40.370+0000] {task_command.py:423} INFO - Running <TaskInstance: bis_pipeline_dag.kafka_to_bronze manual__2025-07-25T01:15:35.843105+00:00 [running]> on host 665ba5283d17
[2025-07-25T01:15:40.531+0000] {taskinstance.py:2480} INFO - Exporting env vars: AIRFLOW_CTX_DAG_OWNER='airflow' AIRFLOW_CTX_DAG_ID='bis_pipeline_dag' AIRFLOW_CTX_TASK_ID='kafka_to_bronze' AIRFLOW_CTX_EXECUTION_DATE='2025-07-25T01:15:35.843105+00:00' AIRFLOW_CTX_TRY_NUMBER='1' AIRFLOW_CTX_DAG_RUN_ID='manual__2025-07-25T01:15:35.843105+00:00'
[2025-07-25T01:15:40.560+0000] {docker.py:359} INFO - Starting docker container from image bitnami/spark:3.3
[2025-07-25T01:15:40.567+0000] {taskinstance.py:2698} ERROR - Task failed with exception
Traceback (most recent call last):
  File "/home/airflow/.local/lib/python3.10/site-packages/docker/api/client.py", line 265, in _raise_for_status
    response.raise_for_status()
  File "/home/airflow/.local/lib/python3.10/site-packages/requests/models.py", line 1021, in raise_for_status
    raise HTTPError(http_error_msg, response=self)
requests.exceptions.HTTPError: 400 Client Error: Bad Request for url: http+docker://localhost/v1.51/containers/create

The above exception was the direct cause of the following exception:

Traceback (most recent call last):
  File "/home/airflow/.local/lib/python3.10/site-packages/airflow/models/taskinstance.py", line 433, in _execute_task
    result = execute_callable(context=context, **execute_callable_kwargs)
  File "/home/airflow/.local/lib/python3.10/site-packages/airflow/providers/docker/operators/docker.py", line 502, in execute
    return self._run_image()
  File "/home/airflow/.local/lib/python3.10/site-packages/airflow/providers/docker/operators/docker.py", line 364, in _run_image
    return self._run_image_with_mounts([*self.mounts, tmp_mount], add_tmp_variable=True)
  File "/home/airflow/.local/lib/python3.10/site-packages/airflow/providers/docker/operators/docker.py", line 391, in _run_image_with_mounts
    self.container = self.cli.create_container(
  File "/home/airflow/.local/lib/python3.10/site-packages/docker/api/container.py", line 439, in create_container
    return self.create_container_from_config(config, name, platform)
  File "/home/airflow/.local/lib/python3.10/site-packages/docker/api/container.py", line 456, in create_container_from_config
    return self._result(res, True)
  File "/home/airflow/.local/lib/python3.10/site-packages/docker/api/client.py", line 271, in _result
    self._raise_for_status(response)
  File "/home/airflow/.local/lib/python3.10/site-packages/docker/api/client.py", line 267, in _raise_for_status
    raise create_api_error_from_http_exception(e) from e
  File "/home/airflow/.local/lib/python3.10/site-packages/docker/errors.py", line 39, in create_api_error_from_http_exception
    raise cls(e, response=response, explanation=explanation) from e
docker.errors.APIError: 400 Client Error for http+docker://localhost/v1.51/containers/create: Bad Request ("invalid JSON: json: cannot unmarshal string into Go struct field HostConfig.HostConfig.Mounts of type mount.Mount")
[2025-07-25T01:15:40.574+0000] {taskinstance.py:1138} INFO - Marking task as FAILED. dag_id=bis_pipeline_dag, task_id=kafka_to_bronze, execution_date=20250725T011535, start_date=20250725T011540, end_date=20250725T011540
[2025-07-25T01:15:40.619+0000] {standard_task_runner.py:107} ERROR - Failed to execute job 12 for task kafka_to_bronze (400 Client Error for http+docker://localhost/v1.51/containers/create: Bad Request ("invalid JSON: json: cannot unmarshal string into Go struct field HostConfig.HostConfig.Mounts of type mount.Mount"); 190)
[2025-07-25T01:15:40.642+0000] {local_task_job_runner.py:234} INFO - Task exited with return code 1
[2025-07-25T01:15:40.656+0000] {taskinstance.py:3280} INFO - 0 downstream tasks scheduled from follow-on schedule check
