[2025-07-24T09:39:32.869+0000] {taskinstance.py:1956} INFO - Dependencies all met for dep_context=non-requeueable deps ti=<TaskInstance: bis_pipeline_dag.kafka_to_bronze manual__2025-07-24T09:39:30.297632+00:00 [queued]>
[2025-07-24T09:39:32.873+0000] {taskinstance.py:1956} INFO - Dependencies all met for dep_context=requeueable deps ti=<TaskInstance: bis_pipeline_dag.kafka_to_bronze manual__2025-07-24T09:39:30.297632+00:00 [queued]>
[2025-07-24T09:39:32.873+0000] {taskinstance.py:2170} INFO - Starting attempt 1 of 1
[2025-07-24T09:39:32.905+0000] {taskinstance.py:2191} INFO - Executing <Task(DockerOperator): kafka_to_bronze> on 2025-07-24 09:39:30.297632+00:00
[2025-07-24T09:39:32.908+0000] {standard_task_runner.py:60} INFO - Started process 209 to run task
[2025-07-24T09:39:32.910+0000] {standard_task_runner.py:87} INFO - Running: ['airflow', 'tasks', 'run', 'bis_pipeline_dag', 'kafka_to_bronze', 'manual__2025-07-24T09:39:30.297632+00:00', '--job-id', '13', '--raw', '--subdir', 'DAGS_FOLDER/bis_pipeline_dag.py', '--cfg-path', '/tmp/tmpxklms065']
[2025-07-24T09:39:32.911+0000] {standard_task_runner.py:88} INFO - Job 13: Subtask kafka_to_bronze
[2025-07-24T09:39:32.978+0000] {task_command.py:423} INFO - Running <TaskInstance: bis_pipeline_dag.kafka_to_bronze manual__2025-07-24T09:39:30.297632+00:00 [running]> on host 382e272d1760
[2025-07-24T09:39:33.126+0000] {taskinstance.py:2480} INFO - Exporting env vars: AIRFLOW_CTX_DAG_OWNER='airflow' AIRFLOW_CTX_DAG_ID='bis_pipeline_dag' AIRFLOW_CTX_TASK_ID='kafka_to_bronze' AIRFLOW_CTX_EXECUTION_DATE='2025-07-24T09:39:30.297632+00:00' AIRFLOW_CTX_TRY_NUMBER='1' AIRFLOW_CTX_DAG_RUN_ID='manual__2025-07-24T09:39:30.297632+00:00'
[2025-07-24T09:39:33.144+0000] {docker.py:486} INFO - Pulling docker image bitname/spark:3.3
[2025-07-24T09:39:35.320+0000] {taskinstance.py:2698} ERROR - Task failed with exception
Traceback (most recent call last):
  File "/home/airflow/.local/lib/python3.10/site-packages/docker/api/client.py", line 265, in _raise_for_status
    response.raise_for_status()
  File "/home/airflow/.local/lib/python3.10/site-packages/requests/models.py", line 1021, in raise_for_status
    raise HTTPError(http_error_msg, response=self)
requests.exceptions.HTTPError: 404 Client Error: Not Found for url: http+docker://localhost/v1.51/images/create?tag=3.3&fromImage=bitname%2Fspark

The above exception was the direct cause of the following exception:

Traceback (most recent call last):
  File "/home/airflow/.local/lib/python3.10/site-packages/airflow/models/taskinstance.py", line 433, in _execute_task
    result = execute_callable(context=context, **execute_callable_kwargs)
  File "/home/airflow/.local/lib/python3.10/site-packages/airflow/providers/docker/operators/docker.py", line 488, in execute
    for output in self.cli.pull(self.image, stream=True, decode=True):
  File "/home/airflow/.local/lib/python3.10/site-packages/docker/api/image.py", line 429, in pull
    self._raise_for_status(response)
  File "/home/airflow/.local/lib/python3.10/site-packages/docker/api/client.py", line 267, in _raise_for_status
    raise create_api_error_from_http_exception(e) from e
  File "/home/airflow/.local/lib/python3.10/site-packages/docker/errors.py", line 39, in create_api_error_from_http_exception
    raise cls(e, response=response, explanation=explanation) from e
docker.errors.ImageNotFound: 404 Client Error for http+docker://localhost/v1.51/images/create?tag=3.3&fromImage=bitname%2Fspark: Not Found ("pull access denied for bitname/spark, repository does not exist or may require 'docker login'")
[2025-07-24T09:39:35.327+0000] {taskinstance.py:1138} INFO - Marking task as FAILED. dag_id=bis_pipeline_dag, task_id=kafka_to_bronze, execution_date=20250724T093930, start_date=20250724T093932, end_date=20250724T093935
[2025-07-24T09:39:35.368+0000] {standard_task_runner.py:107} ERROR - Failed to execute job 13 for task kafka_to_bronze (404 Client Error for http+docker://localhost/v1.51/images/create?tag=3.3&fromImage=bitname%2Fspark: Not Found ("pull access denied for bitname/spark, repository does not exist or may require 'docker login'"); 209)
[2025-07-24T09:39:35.410+0000] {local_task_job_runner.py:234} INFO - Task exited with return code 1
[2025-07-24T09:39:35.425+0000] {taskinstance.py:3280} INFO - 0 downstream tasks scheduled from follow-on schedule check
