[2025-07-24T09:38:36.608+0000] {taskinstance.py:1956} INFO - Dependencies all met for dep_context=non-requeueable deps ti=<TaskInstance: bis_pipeline_dag.kafka_to_bronze manual__2025-07-24T09:38:32.622957+00:00 [queued]>
[2025-07-24T09:38:36.612+0000] {taskinstance.py:1956} INFO - Dependencies all met for dep_context=requeueable deps ti=<TaskInstance: bis_pipeline_dag.kafka_to_bronze manual__2025-07-24T09:38:32.622957+00:00 [queued]>
[2025-07-24T09:38:36.613+0000] {taskinstance.py:2170} INFO - Starting attempt 1 of 1
[2025-07-24T09:38:36.684+0000] {taskinstance.py:2191} INFO - Executing <Task(DockerOperator): kafka_to_bronze> on 2025-07-24 09:38:32.622957+00:00
[2025-07-24T09:38:36.687+0000] {standard_task_runner.py:60} INFO - Started process 194 to run task
[2025-07-24T09:38:36.689+0000] {standard_task_runner.py:87} INFO - Running: ['airflow', 'tasks', 'run', 'bis_pipeline_dag', 'kafka_to_bronze', 'manual__2025-07-24T09:38:32.622957+00:00', '--job-id', '11', '--raw', '--subdir', 'DAGS_FOLDER/bis_pipeline_dag.py', '--cfg-path', '/tmp/tmpawo3w9xq']
[2025-07-24T09:38:36.690+0000] {standard_task_runner.py:88} INFO - Job 11: Subtask kafka_to_bronze
[2025-07-24T09:38:36.764+0000] {task_command.py:423} INFO - Running <TaskInstance: bis_pipeline_dag.kafka_to_bronze manual__2025-07-24T09:38:32.622957+00:00 [running]> on host 382e272d1760
[2025-07-24T09:38:36.941+0000] {taskinstance.py:2480} INFO - Exporting env vars: AIRFLOW_CTX_DAG_OWNER='airflow' AIRFLOW_CTX_DAG_ID='bis_pipeline_dag' AIRFLOW_CTX_TASK_ID='kafka_to_bronze' AIRFLOW_CTX_EXECUTION_DATE='2025-07-24T09:38:32.622957+00:00' AIRFLOW_CTX_TRY_NUMBER='1' AIRFLOW_CTX_DAG_RUN_ID='manual__2025-07-24T09:38:32.622957+00:00'
[2025-07-24T09:38:36.943+0000] {taskinstance.py:2698} ERROR - Task failed with exception
Traceback (most recent call last):
  File "/home/airflow/.local/lib/python3.10/site-packages/urllib3/connectionpool.py", line 791, in urlopen
    response = self._make_request(
  File "/home/airflow/.local/lib/python3.10/site-packages/urllib3/connectionpool.py", line 497, in _make_request
    conn.request(
  File "/home/airflow/.local/lib/python3.10/site-packages/urllib3/connection.py", line 395, in request
    self.endheaders()
  File "/usr/local/lib/python3.10/http/client.py", line 1278, in endheaders
    self._send_output(message_body, encode_chunked=encode_chunked)
  File "/usr/local/lib/python3.10/http/client.py", line 1038, in _send_output
    self.send(msg)
  File "/usr/local/lib/python3.10/http/client.py", line 976, in send
    self.connect()
  File "/home/airflow/.local/lib/python3.10/site-packages/docker/transport/unixconn.py", line 27, in connect
    sock.connect(self.unix_socket)
PermissionError: [Errno 13] Permission denied

During handling of the above exception, another exception occurred:

Traceback (most recent call last):
  File "/home/airflow/.local/lib/python3.10/site-packages/requests/adapters.py", line 486, in send
    resp = conn.urlopen(
  File "/home/airflow/.local/lib/python3.10/site-packages/urllib3/connectionpool.py", line 845, in urlopen
    retries = retries.increment(
  File "/home/airflow/.local/lib/python3.10/site-packages/urllib3/util/retry.py", line 470, in increment
    raise reraise(type(error), error, _stacktrace)
  File "/home/airflow/.local/lib/python3.10/site-packages/urllib3/util/util.py", line 38, in reraise
    raise value.with_traceback(tb)
  File "/home/airflow/.local/lib/python3.10/site-packages/urllib3/connectionpool.py", line 791, in urlopen
    response = self._make_request(
  File "/home/airflow/.local/lib/python3.10/site-packages/urllib3/connectionpool.py", line 497, in _make_request
    conn.request(
  File "/home/airflow/.local/lib/python3.10/site-packages/urllib3/connection.py", line 395, in request
    self.endheaders()
  File "/usr/local/lib/python3.10/http/client.py", line 1278, in endheaders
    self._send_output(message_body, encode_chunked=encode_chunked)
  File "/usr/local/lib/python3.10/http/client.py", line 1038, in _send_output
    self.send(msg)
  File "/usr/local/lib/python3.10/http/client.py", line 976, in send
    self.connect()
  File "/home/airflow/.local/lib/python3.10/site-packages/docker/transport/unixconn.py", line 27, in connect
    sock.connect(self.unix_socket)
urllib3.exceptions.ProtocolError: ('Connection aborted.', PermissionError(13, 'Permission denied'))

During handling of the above exception, another exception occurred:

Traceback (most recent call last):
  File "/home/airflow/.local/lib/python3.10/site-packages/docker/api/client.py", line 213, in _retrieve_server_version
    return self.version(api_version=False)["ApiVersion"]
  File "/home/airflow/.local/lib/python3.10/site-packages/docker/api/daemon.py", line 181, in version
    return self._result(self._get(url), json=True)
  File "/home/airflow/.local/lib/python3.10/site-packages/docker/utils/decorators.py", line 44, in inner
    return f(self, *args, **kwargs)
  File "/home/airflow/.local/lib/python3.10/site-packages/docker/api/client.py", line 236, in _get
    return self.get(url, **self._set_request_timeout(kwargs))
  File "/home/airflow/.local/lib/python3.10/site-packages/requests/sessions.py", line 602, in get
    return self.request("GET", url, **kwargs)
  File "/home/airflow/.local/lib/python3.10/site-packages/requests/sessions.py", line 589, in request
    resp = self.send(prep, **send_kwargs)
  File "/home/airflow/.local/lib/python3.10/site-packages/requests/sessions.py", line 703, in send
    r = adapter.send(request, **kwargs)
  File "/home/airflow/.local/lib/python3.10/site-packages/requests/adapters.py", line 501, in send
    raise ConnectionError(err, request=request)
requests.exceptions.ConnectionError: ('Connection aborted.', PermissionError(13, 'Permission denied'))

The above exception was the direct cause of the following exception:

Traceback (most recent call last):
  File "/home/airflow/.local/lib/python3.10/site-packages/airflow/models/taskinstance.py", line 433, in _execute_task
    result = execute_callable(context=context, **execute_callable_kwargs)
  File "/home/airflow/.local/lib/python3.10/site-packages/airflow/providers/docker/operators/docker.py", line 485, in execute
    if self.force_pull or not self.cli.images(name=self.image):
  File "/home/airflow/.local/lib/python3.10/site-packages/airflow/providers/docker/operators/docker.py", line 355, in cli
    return self.hook.api_client
  File "/usr/local/lib/python3.10/functools.py", line 981, in __get__
    val = self.func(instance)
  File "/home/airflow/.local/lib/python3.10/site-packages/airflow/providers/docker/hooks/docker.py", line 120, in api_client
    client = APIClient(
  File "/home/airflow/.local/lib/python3.10/site-packages/docker/api/client.py", line 197, in __init__
    self._version = self._retrieve_server_version()
  File "/home/airflow/.local/lib/python3.10/site-packages/docker/api/client.py", line 220, in _retrieve_server_version
    raise DockerException(
docker.errors.DockerException: Error while fetching server API version: ('Connection aborted.', PermissionError(13, 'Permission denied'))
[2025-07-24T09:38:37.083+0000] {taskinstance.py:1138} INFO - Marking task as FAILED. dag_id=bis_pipeline_dag, task_id=kafka_to_bronze, execution_date=20250724T093832, start_date=20250724T093836, end_date=20250724T093837
[2025-07-24T09:38:37.142+0000] {standard_task_runner.py:107} ERROR - Failed to execute job 11 for task kafka_to_bronze (Error while fetching server API version: ('Connection aborted.', PermissionError(13, 'Permission denied')); 194)
[2025-07-24T09:38:37.182+0000] {local_task_job_runner.py:234} INFO - Task exited with return code 1
[2025-07-24T09:38:37.197+0000] {taskinstance.py:3280} INFO - 0 downstream tasks scheduled from follow-on schedule check
